Workbook

Sheet README
A1: CCPC Corporate Tax Planning & Compliance Intake Workbook
A2: COMPLETED SAMPLE SUBMISSION — Northern Peak Consulting Inc., FY2025 (Alberta CCPC) | Prepared for professional review — not a substitute for filed tax advice
A4: PURPOSE
A5: This workbook collects the complete financial, ownership, and compliance information needed to assess a CCPC's current-year tax position (federal + provincial corporate income tax, GST/HST, payroll remittances) and to model forward-looking planning strategies (salary vs. dividend mix, SBD protection, RDTOH/GRIP/CDA recovery, CCA timing, associated-corporation structuring, TOSI exposure). It is designed for use by, or in collaboration with, an accountant or tax professional.
A8: HOW TO USE THIS WORKBOOK
A9: 1. Start at the '1. Entity Setup' tab. Select your Province/Territory from the dropdown — this drives all rate lookups on the Dashboard.
A11: 2. Work through each tab in order (tab colour indicates status — see legend below). Each table's first data row is a greyed-out SAMPLE row showing a realistic complex CCPC scenario ('Northern Peak Consulting Inc.') — read it for guidance, then enter your own data in the rows below it.
A13: 3. Cells shaded yellow are for your input. Cells with grey italic text are placeholder examples (e.g., 'e.g., 123456789RC0001') — overwrite them with your own figures.
A15: 4. Do not edit cells with black or green text — these contain formulas that calculate automatically from your inputs.
A17: 5. If any prior-year balance (RDTOH, GRIP, CDA, loss carryforwards) is unknown, enter 0 and flag it for your accountant to confirm from the prior-year T2 schedules — do NOT guess, as these materially change the output.
A19: 6. Review the 'Dashboard' tab last — it summarizes current tax position and planning flags computed from everything you entered.
A22: COLOUR & FORMAT LEGEND
A23: Style | B23: Meaning
A24: Yellow fill, blue text | B24: Your input — type your own figures here
A25: Grey fill, italic text (marked SAMPLE) | B25: Illustrative example row — read for format, then overwrite/replace below it
A26: Grey italic text only (no fill change) | B26: Placeholder example text — delete and type your real value
A27: Black text | B27: Calculated formula — do not overwrite
A28: Green text | B28: Value linked from another tab — do not overwrite
A29: Red italic text | B29: Warning / rule that needs professional confirmation
A31: WORKBOOK CONTENTS
A32: • 1. Entity Setup
A33: • 2. Provincial Allocation (Multi-PE)
A34: • 3. Income Statement
A35: • 4. Balance Sheet
A36: • 5. Prior-Year Tax Attributes
A37: • 6. CCA Continuity
A38: • 7. Associated Corporations
A39: • 8. Shareholders & TOSI
A40: • 9. Payroll Register
A41: • 10. GST-HST
A42: • 11. Instalments & Compliance
... A49: Tax rates, thresholds, and credit amounts shown (including the 'Province Rate Reference' tab) are illustrative approximations based on general knowledge and are NOT guaranteed current. Federal and provincial rates, the SBD threshold, GST/HST rates, and CPP/EI figures change annually (sometimes mid-year). VERIFY every rate against the current CRA and provincial government publications before relying on any output. This workbook is a planning and organizing tool only — it does not replace a filed tax return, a professional's sign-off, or advice on elections, reorganizations, or anything with GAAR (general anti-avoidance rule) exposure.

Sheet Dashboard
A1: DASHBOARD — Current Position & Planning Summary
A2: Calculated from the completed intake for Northern Peak Consulting Inc., FY2025. ⚠ Uses illustrative rates from 'Province Rate Reference' — verify before relying on any figure. This is a planning aid, not a filed return.
A4: ENTITY SNAPSHOT
A5: Legal Name | B5: ='1. Entity Setup'!C4 -> Northern Peak Consulting Inc.
A6: Province (drives rates below) | B6: ='1. Entity Setup'!$C$12 -> Alberta
A7: Tax Year | B7: ='1. Entity Setup'!$C$18 -> 2025
A8: Associated with Other Corporations? | B8: ='1. Entity Setup'!$C$28 -> Yes
A10: RATES APPLIED (looked up from Province Rate Reference, based on province above)
A11: Combined Small Business Rate (Fed+Prov) | B11: =INDEX('Province Rate Reference'!$C$5:$C$17,MATCH(B6,'Province Rate Reference'!$A$5:$A$17,0)) -> 0.11
A12: Combined General Rate (Fed+Prov) | B12: =INDEX('Province Rate Reference'!$B$5:$B$17,MATCH(B6,'Province Rate Reference'!$A$5:$A$17,0)) -> 0.23
A13: Estimated Investment-Income Rate (Fed+Prov) | B13: =B12+0.2367 -> 0.4667 | C13: Approximation: general rate + ~23.67pt federal add-on for the loss of the general rate reduction plus the refundable tax on investment income. Verify exact figure.
A15: 1. SMALL BUSINESS DEDUCTION (SBD) — CURRENT POSITION
A16: Net Active Business Income (this entity) | B16: ='3. Income Statement'!B47 -> 190000
A17: Aggregate Investment Income (this entity, current year — used as proxy for prior-year AAII test) | B17: ='3. Income Statement'!B48 -> 55000
A18: Passive-Income Grind (reduction to $500K limit: 5 × (AAII − $50,000), capped) | B18: =MIN(500000,MAX(0,(B17-50000)*5)) -> 25000
A19: Group Taxable Capital Employed in Canada (from Associated Corporations tab) | B19: ='7. Associated Corporations'!E10 -> 1565000
A20: Taxable-Capital Grind (reduction: $500K × (Taxable Capital − $10M) / $40M, capped) | B20: =MIN(500000,MAX(0,(B19-10000000)/40000000*500000)) -> 0
A21: Federal SBD Limit After Grinds (500,000 − greater of the two grinds) | B21: =MAX(0,500000-MAX(B18,B20)) -> 475000
A22: This Entity's SBD Limit (lesser of grind-adjusted limit and Schedule 23 allocation) | B22: =MIN(B21,IF('1. Entity Setup'!$C$28="Yes",IFERROR(VLOOKUP("Northern Peak Consulting Inc. (this entity)",'7. Associated Corporations'!A5:F9,6,FALSE()),500000),500000)) -> 350000 | C22: If associated, pulls this entity's row from the Schedule 23 allocation table by name; if not associated, defaults to the full $500K (post-grind).
A23: Active Business Income Taxed at SBD Rate | B23: =MIN(B16,B22) -> 190000
A24: Active Business Income Taxed at General Rate (excess over SBD limit) | B24: =MAX(0,B16-B22) -> 0
A25: ⚠ Passive-Income Grind Flag | B25: =IF(B18>0,"GRINDING — AAII over $50,000","OK — under $50,000 threshold") -> GRINDING — AAII over $50,000
A27: 2. CURRENT-YEAR CORPORATE TAX ESTIMATE (federal + provincial)
A28: Tax on SBD-Rate Income | B28: =B23*B11 -> 20900
A29: Tax on General-Rate Active Business Income | B29: =B24*B12 -> 0
A30: Tax on Aggregate Investment Income | B30: =B17*B13 -> 25668.5
A31: ESTIMATED TOTAL CORPORATE TAX PAYABLE | B31: =B28+B29+B30 -> 46568.5
A32: Less: Instalments Already Paid | B32: ='11. Instalments & Compliance'!B20 -> 40500
A33: Balance Owing / (Refund) at Year-End | B33: =B31-B32 -> 6068.5
A34: Instalments Likely Required Next Year? | B34: =IF(B31>3000,"Yes","No") -> Yes
A36: 3. RDTOH / GRIP / CDA — RECOVERABLE TAX POOLS
A37: Non-Eligible RDTOH Addition This Year (≈30⅔% of Aggregate Investment Income) | B37: =B17*0.3067 -> 16868.5
A38: Non-Eligible RDTOH — Opening Balance | B38: ='5. Prior-Year Tax Attributes'!C6 -> 42300
A39: Non-Eligible RDTOH — Closing Balance (Opening + Addition) | B39: =B38+B37 -> 59168.5
A40: Eligible RDTOH — Opening/Closing Balance (carried forward) | B40: ='5. Prior-Year Tax Attributes'!C5 -> 18500
A41: Non-Eligible Dividend Needed to Fully Recover Non-Eligible RDTOH (÷38⅓%) | B41: =B39/0.3833 -> 154366.03
A42: Eligible Dividend Needed to Fully Recover Eligible RDTOH (÷38⅓%) | B42: =B40/0.3833 -> 48265.067
A43: GRIP Balance Available (for lower-taxed ELIGIBLE dividends) | B43: ='5. Prior-Year Tax Attributes'!C9 -> 65000
A44: CDA Balance Available (paid 100% TAX-FREE by election — T2054) | B44: ='5. Prior-Year Tax Attributes'!C12 -> 22000
A45: ⚠ Action Flag | B45: =IF(B44>0,"CDA balance sitting idle — consider a capital dividend election","No CDA balance available") -> CDA balance sitting idle — consider a capital dividend election
...

Sheet 1. Entity Setup
A1: 1. Entity Setup
A3: CORPORATE IDENTIFICATION
A4: Legal Name of Corporation | C4: Northern Peak Consulting Inc.
A5: CRA Business Number (BN) | C5: 123456789
A6: Corporation Program Account (RC) | C6: RC0001
A7: Incorporation Date | C7: 2016-04-01
A8: Industry / NAICS Code | C8: 541611 - Management Consulting
A10: PROVINCE & JURISDICTION (drives all rate lookups)
A11: Province/Territory of Incorporation | C11: Alberta
A12: Primary Province of Operation | C12: Alberta | D12: Used on Dashboard for primary rate lookup.
A13: Multiple Permanent Establishments in >1 Province? | C13: Yes | D13: If Yes, complete '2. Provincial Allocation' tab (Schedule 5).
A15: FISCAL PERIOD
A16: Fiscal Year Start Date | C16: 2025-01-01
A17: Fiscal Year End Date | C17: 2025-12-31
A18: Tax Year | C18: 2025
A19: First Year of Operation? | C19: No
A20: Short/Stub Year? (prorates SBD limit & instalment threshold) | C20: No
A21: Wind-Up / Final Year? | C21: No
A23: CCPC STATUS
A24: Canadian-Controlled Private Corporation Confirmed? | C24: Yes | D24: Control test: >50% of voting shares held by Canadian residents; not controlled by non-residents or a public corp.
A25: Any change of control this tax year? | C25: No | D25: A change of control can end the fiscal year early and restrict loss carryforwards — flag for accountant.
A27: GROUP STRUCTURE
A28: Associated with Other Corporation(s)? | C28: Yes | D28: If Yes, complete '7. Associated Corporations' tab — the $500K SBD limit is shared across the group.
A29: Number of Shareholders | C29: 3

Sheet 2. Provincial Allocation
A1: 2. Provincial Income Allocation (Schedule 5) — only if operating in multiple provinces
A2: Complete only if '1. Entity Setup' answered Yes to multiple permanent establishments. Allocation % = average of (revenue in province ÷ total revenue) and (wages in province ÷ total wages). Total allocation must equal 100%.
A4: Province/Territory | B4: Gross Revenue Attributable ($) | C4: Salaries & Wages Paid ($) | D4: % of Total Revenue | E4: % of Total Wages | F4: Allocation % (avg) | G4: Taxable Income Allocated ($) | H4: Notes
A5: Alberta (Head Office) | B5: 850000 | C5: 420000 | D5: =B5/SUM($B$5:$B$6) -> 0.70833333 | E5: =C5/SUM($C$5:$C$6) -> 0.7 | F5: =AVERAGE(D5:E5) -> 0.70416667 | G5: =F5*'3. Income Statement'!$B$49 -> 200687.5 | H5: e.g., head-office province
A6: Ontario (Branch Office) | B6: 350000 | C6: 180000 | D6: =B6/SUM($B$5:$B$6) -> 0.29166667 | E6: =C6/SUM($C$5:$C$6) -> 0.3 | F6: =AVERAGE(D6:E6) -> 0.29583333 | G6: =F6*'3. Income Statement'!$B$49 -> 84312.5 | H6: e.g., branch office
D7: =IF(SUM($B$7:$B$12)=0,0,B7/SUM($B$7:$B$12)) -> 0 | E7: =IF(SUM($C$7:$C$12)=0,0,C7/SUM($C$7:$C$12)) -> 0 | F7: =AVERAGE(D7:E7) -> 0 | G7: =F7*'3. Income Statement'!$B$49 -> 0
D8: =IF(SUM($B$7:$B$12)=0,0,B8/SUM($B$7:$B$12)) -> 0 | E8: =IF(SUM($C$7:$C$12)=0,0,C8/SUM($C$7:$C$12)) -> 0 | F8: =AVERAGE(D8:E8) -> 0 | G8: =F8*'3. Income Statement'!$B$49 -> 0
D9: =IF(SUM($B$7:$B$12)=0,0,B9/SUM($B$7:$B$12)) -> 0 | E9: =IF(SUM($C$7:$C$12)=0,0,C9/SUM($C$7:$C$12)) -> 0 | F9: =AVERAGE(D9:E9) -> 0 | G9: =F9*'3. Income Statement'!$B$49 -> 0
D10: =IF(SUM($B$7:$B$12)=0,0,B10/SUM($B$7:$B$12)) -> 0 | E10: =IF(SUM($C$7:$C$12)=0,0,C10/SUM($C$7:$C$12)) -> 0 | F10: =AVERAGE(D10:E10) -> 0 | G10: =F10*'3. Income Statement'!$B$49 -> 0
D11: =IF(SUM($B$7:$B$12)=0,0,B11/SUM($B$7:$B$12)) -> 0 | E11: =IF(SUM($C$7:$C$12)=0,0,C11/SUM($C$7:$C$12)) -> 0 | F11: =AVERAGE(D11:E11) -> 0 | G11: =F11*'3. Income Statement'!$B$49 -> 0
D12: =IF(SUM($B$7:$B$12)=0,0,B12/SUM($B$7:$B$12)) -> 0 | E12: =IF(SUM($C$7:$C$12)=0,0,C12/SUM($C$7:$C$12)) -> 0 | F12: =AVERAGE(D12:E12) -> 0 | G12: =F12*'3. Income Statement'!$B$49 -> 0
A14: TOTAL | B14: =SUM(B5:B12) -> 1200000 | C14: =SUM(C5:C12) -> 600000 | F14: =SUM(F5:F12) -> 1 | H14: Should equal 100% if all PEs listed

Sheet 3. Income Statement
A1: 3. Income Statement — Current Fiscal Year
A3: Line Item | B3: Amount ($) | C3: Classification | D3: Notes
A4: REVENUE
A5: Consulting Fees — Alberta Clients | B5: 850000
A6: Consulting Fees — Ontario Clients | B6: 350000
A9: Total Revenue | B9: =SUM(B5:B8) -> 1200000
A11: COST OF GOODS SOLD
A12: Subcontractor / Direct Delivery Costs | B12: 180000
A14: Total COGS | B14: =SUM(B12:B13) -> 180000
A15: Gross Profit | B15: =B9-B14 -> 1020000
A17: OPERATING EXPENSES
A18: Salaries & Wages (non-owner staff) | B18: 600000
A19: Rent | B19: 60000
A20: Professional Fees (Legal/Accounting) | B20: 25000
A21: Meals & Entertainment | B21: 8000 | D21: Only 50% is deductible for tax / eligible for ITC — see GST-HST tab.
A22: Motor Vehicle Expenses | B22: 15000
A23: Insurance | B23: 10000
A24: Amortization/Depreciation (book) | B24: 45000 | D24: Book amortization only — CCA claimed separately, see '6. CCA Continuity' tab.
A25: Office & Administration | B25: 30000
A26: Marketing & Advertising | B26: 20000
A27: Interest Expense | B27: 12000
A28: Other Operating Expenses | B28: 5000
A31: Total Operating Expenses | B31: =SUM(B18:B30) -> 830000
A32: Operating Income (= Net Active Business Income) | B32: =B15-B31 -> 190000
A34: OTHER INCOME / (EXPENSE) — classify each line for SBD passive-income tracking
A35: Interest Income | B35: 12000 | C35: Aggregate Investment Income
A36: Dividends Received — Connected Corporation (Northern Peak Holdings Inc.) | B36: 40000 | C36: Exempt/Other | D36: Connected (sister corp under common control, s.186(4)): deductible under s.112, NOT active business income. Part IV = this corp's share of the payer's dividend refund - enter it in the holdco section below.
A37: Dividends Received — Portfolio (Non-Connected) | B37: 15000 | C37: Aggregate Investment Income | D37: May trigger Part IV tax — see Dashboard.
A38: Taxable Capital Gains (net, 1/2 of realized gain) | B38: 20000 | C38: Aggregate Investment Income | D38: Other 1/2 credits the Capital Dividend Account — see '13. Special Items'.
A39: Net Rental Income | B39: 8000 | C39: Aggregate Investment Income | D39: Passive unless the corp meets the active-rental test (5+ full-time employees).
A40: Foreign Income (net of foreign tax) | B40: 0 | C40: Foreign Income
A43: Total Other Income | B43: =SUM(B35:B42) -> 95000
A44: NET INCOME BEFORE TAX | B44: =B32+B43 -> 285000
A46: SUMMARY FOR TAX CLASSIFICATION (feeds Dashboard)
A47: Net Active Business Income (for SBD numerator) | B47: =B32 -> 190000
A48: Aggregate Investment Income (for passive-income grind) | B48: =SUMIF(C35:C42,"Aggregate Investment Income",B35:B42) -> 55000
A49: Net Income Before Tax (total) | B49: =B44 -> 285000
A51: HOLDCO / INVESTMENT DETAIL (optional) - fill this if the corporation received dividends or realized capital gains; it replaces the single AAII figure above
A52: Interest & Net Passive Rental Income (Part I) | B52: 20000 | D52: Interest, net passive rents, other property income. Taxed under Part I at the investment-income rate.
A53: Taxable Capital Gains (taxable portion only) | B53: 20000 | D53: Enter the TAXABLE portion only (1/2 of the net gain). The other half credits the CDA automatically.
...

Sheet 4. Balance Sheet
A1: 4. Balance Sheet — As at Fiscal Year-End
A3: Line Item | B3: Amount ($) | D3: Notes
A4: ASSETS
A5: Cash & Cash Equivalents | B5: 145000
A6: Accounts Receivable | B6: 210000
A7: Inventory | B7: 0
A8: Prepaid Expenses | B8: 15000
A9: Portfolio Investments (marketable securities) | B9: 380000 | D9: Generates the interest/dividend/capital-gain income on the Income Statement tab.
A10: Capital Assets, Net of Accumulated Amortization | B10: 260000 | D10: Ties to closing UCC on '6. CCA Continuity' (book vs. tax basis will differ).
A11: Shares of Connected Corporation (Northern Peak Holdings Inc.) | B11: 100000 | D11: See '7. Associated Corporations'.
A12: Cash Surrender Value — Life Insurance | B12: 35000 | D12: See '13. Special Items'.
A15: Total Assets | B15: =SUM(B5:B14) -> 1145000
A17: LIABILITIES
A18: Accounts Payable & Accrued Liabilities | B18: 95000
A19: GST/HST Payable | B19: 12000 | D19: Ties to '10. GST-HST' tab.
A20: Shareholder Loans Payable (corp owes shareholder) | B20: 40000
A21: Shareholder Loans Receivable (shareholder owes corp) | B21: 25000 | D21: s.15(2) — if not repaid within 1 year after year-end, taxable to shareholder. See '8. Shareholders & TOSI'.
A22: Current Portion of Long-Term Debt | B22: 30000
A23: Long-Term Debt | B23: 150000
A24: Deferred Revenue | B24: 20000
A27: Total Liabilities | B27: =SUM(B18:B26) -> 372000
A29: SHAREHOLDERS' EQUITY
A30: Common Share Capital | B30: 100
A31: Preferred Share Capital (Class C — Estate Freeze) | B31: 90000
A32: Retained Earnings — Opening | B32: 397900
A33: Net Income for the Year (linked from Income Statement) | B33: ='3. Income Statement'!B49 -> 285000
A34: Total Shareholders' Equity | B34: =SUM(B30:B33) -> 773000
A36: Total Liabilities + Equity (should equal Total Assets) | B36: =B27+B34 -> 1145000
A37: Balance Check (should be $0) | B37: =B15-(B27+B34) -> 0
A39: TAXABLE CAPITAL EMPLOYED IN CANADA (for SR&ED limit & large-CCPC SBD/passive grind)
A40: Taxable Capital = Total Assets + certain reserves/loans − certain investments (simplified) | D40: Grinds SBD limit and the SR&ED expenditure limit once the GROUP's taxable capital exceeds $10M (fully eliminated at $50M). Aggregate with associated corps on '7. Associated Corporations'.
A41: Estimated Taxable Capital Employed in Canada (this entity) | B41: =B15 -> 1145000 | D41: Simplified proxy = Total Assets. Confirm exact calculation with accountant (Part I.3-style definition retained federally for this test).

Sheet 5. Prior-Year Tax Attributes
A1: 5. Prior-Year Tax Attribute Balances (Opening, from prior T2 Schedules)
A2: ⚠ These balances do NOT reset annually and are the most common source of missed tax recovery. If unknown, enter 0 and flag for your accountant to confirm from the prior-year T2 Schedules 3, 7, and 53 — never guess.
A4: REFUNDABLE DIVIDEND TAX ON HAND (RDTOH) — Schedule 3
A5: Eligible RDTOH — Opening Balance | C5: 18500 | D5: From eligible portfolio dividends received; refunded at 38⅓% of eligible dividends paid out.
A6: Non-Eligible RDTOH — Opening Balance | C6: 42300 | D6: From Part I tax on investment income + Part IV tax; refunded at 38⅓% of non-eligible dividends paid out.
A8: GENERAL RATE INCOME POOL (GRIP) — Schedule 53
A9: GRIP — Opening Balance | C9: 65000 | D9: Capacity to pay lower-taxed ELIGIBLE dividends (from income taxed at the general corporate rate).
A11: CAPITAL DIVIDEND ACCOUNT (CDA)
A12: CDA — Opening Balance | C12: 22000 | D12: Non-taxable 1/2 of realized capital gains + life insurance proceeds in excess of ACB; paid out 100% tax-free by election (T2054).
A14: NON-CAPITAL LOSS CARRYFORWARDS (20-year carryforward)
A15: Year of Origin | B15: Amount ($) | C15: Expiry Year | D15: Notes
A16: 2022 | B16: 15000 | C16: =A16+20 -> 2042
A17: 2023 | B17: 8000 | C17: =IF(A17=0,0,A17+20) -> 2043
C18: =IF(A18=0,0,A18+20) -> 0
C19: =IF(A19=0,0,A19+20) -> 0
A21: NET CAPITAL LOSS CARRYFORWARDS (indefinite — usable only vs. capital gains)
A22: Year of Origin | B22: Amount ($) | D22: Notes
A23: 2021 | B23: 5000
A26: OTHER CARRYFORWARDS
A27: Unused SR&ED Investment Tax Credit Carryforward | C27: 0 | D27: 20-year carryforward, or refundable if CCPC and under expenditure limit — see '12. Credits & Incentives'.
A28: Unused Foreign Tax Credit Carryforward | C28: 0
A30: Prior-Year Adjusted Aggregate Investment Income (for SBD grind) | D30: Leave BLANK if unknown - the agent then uses the current year as a proxy and flags it. The SBD grind legally uses the prior year's figure.

Sheet 6. CCA Continuity
A1: 6. Capital Cost Allowance (CCA) Continuity Schedule
A3: CCA Class | B3: Opening UCC ($) | C3: Additions ($) | D3: Immediate Expensing / AIIP? | E3: Disposals — Proceeds ($) | F3: Adjusted UCC Base ($) | G3: CCA Rate | H3: CCA Claimed ($) | I3: Closing UCC ($) | J3: Notes
A4: Class 1 - Buildings (4%) | B4: 180000 | C4: 0 | D4: No | E4: 0 | F4: =B4+C4-E4-IF(D4="Yes",0,C4*0.5) -> 180000 | G4: 0.04 | H4: =MIN(F4*G4, B4+C4-E4) -> 7200 | I4: =B4+C4-E4-H4 -> 172800 | J4: Half-year rule N/A — building already in service.
A5: Class 8 - Furniture & Equipment (20%) | B5: 45000 | C5: 12000 | D5: No | E5: 0 | F5: =B5+C5-E5-IF(D5="Yes",0,C5*0.5) -> 51000 | G5: 0.2 | H5: =MIN(F5*G5, B5+C5-E5) -> 10200 | I5: =B5+C5-E5-H5 -> 46800 | J5: Half-year rule applies to additions.
A6: Class 10 - Vehicles (30%) | B6: 22000 | C6: 0 | D6: No | E6: 0 | F6: =B6+C6-E6-IF(D6="Yes",0,C6*0.5) -> 22000 | G6: 0.3 | H6: =MIN(F6*G6, B6+C6-E6) -> 6600 | I6: =B6+C6-E6-H6 -> 15400
A7: Class 50 - Computer Equipment (55%) | B7: 8000 | C7: 15000 | D7: Yes | E7: 0 | F7: =B7+C7-E7-IF(D7="Yes",0,C7*0.5) -> 23000 | G7: 0.55 | H7: =MIN(F7*G7, B7+C7-E7) -> 12650 | I7: =B7+C7-E7-H7 -> 10350 | J7: CCPC immediate expensing — up to $1.5M/yr shared across associated group.
A8: Class 14.1 - Goodwill/Intangibles (5%) | B8: 5000 | C8: 0 | D8: No | E8: 0 | F8: =B8+C8-E8-IF(D8="Yes",0,C8*0.5) -> 5000 | G8: 0.05 | H8: =MIN(F8*G8, B8+C8-E8) -> 250 | I8: =B8+C8-E8-H8 -> 4750 | J8: Post-2016 pool; no half-year rule.
F9: =B9+C9-E9-IF(D9="Yes",0,C9*0.5) -> 0 | H9: =MIN(F9*G9, B9+C9-E9) -> 0 | I9: =B9+C9-E9-H9 -> 0
F10: =B10+C10-E10-IF(D10="Yes",0,C10*0.5) -> 0 | H10: =MIN(F10*G10, B10+C10-E10) -> 0 | I10: =B10+C10-E10-H10 -> 0
F11: =B11+C11-E11-IF(D11="Yes",0,C11*0.5) -> 0 | H11: =MIN(F11*G11, B11+C11-E11) -> 0 | I11: =B11+C11-E11-H11 -> 0
F12: =B12+C12-E12-IF(D12="Yes",0,C12*0.5) -> 0 | H12: =MIN(F12*G12, B12+C12-E12) -> 0 | I12: =B12+C12-E12-H12 -> 0
A13: TOTAL | B13: =SUM(B4:B12) -> 260000 | C13: =SUM(C4:C12) -> 27000 | E13: =SUM(E4:E12) -> 0 | H13: =SUM(H4:H12) -> 36900 | I13: =SUM(I4:I12) -> 250100
A15: Notes: Half-year rule (50% of net additions) is approximated above — the 2024+ Accelerated Investment Incentive Property (AIIP) rules and immediate expensing (CCPC-specific, up to $1.5M/year shared across the associated group) can override the half-year rule; mark 'Yes' in the Immediate Expensing/AIIP column where applicable. Class 10.1 (luxury vehicles) and Class 13 (leaseholds) have additional restrictions not modelled in this simplified continuity — confirm treatment with your accountant. Dispositions with proceeds exceeding UCC may trigger recapture (income) or, if a class empties with a remaining balance, a terminal loss.

Sheet 7. Associated Corporations
A1: 7. Associated Corporations & SBD Allocation (Schedule 23)
A2: The $500,000 federal Small Business Deduction limit (and each province's own SBD threshold) is SHARED across all associated corporations (control test, s.256) — the group must file an agreement (Schedule 23) allocating it. 'Connected' (ownership test, s.186(4)) is a DIFFERENT test that governs intercorporate dividend/Part IV tax treatment, not SBD sharing.
A4: Corporation Name | B4: Relationship | C4: Ownership % | D4: Active Business Income ($) | E4: Taxable Capital Employed ($) | F4: SBD Limit Allocated ($) | G4: Notes
A5: Northern Peak Consulting Inc. (this entity) | B5: Self/Principal | C5: 1 | D5: ='3. Income Statement'!B47 -> 190000 | E5: ='4. Balance Sheet'!B41 -> 1145000 | F5: 350000 | G5: Allocated 70% of the $500K limit per Schedule 23 agreement.
A6: Northern Peak Holdings Inc. | B6: Sister/Affiliate (Common Ownership) | C6: 1 | D6: 60000 | E6: 420000 | F6: 150000 | G6: Holds portfolio investments & pays dividends up to Consulting Inc. — allocated 30% of the $500K limit.
A10: TOTAL | D10: =SUM(D5:D9) -> 250000 | E10: =SUM(E5:E9) -> 1565000 | F10: =SUM(F5:F9) -> 500000
A11: Check: Total SBD Allocated should equal $500,000 | F11: =F10-500000 -> 0
A13: Schedule 23 SBD Allocation Agreement Filed? | C13: Yes

Sheet 8. Shareholders & TOSI
A1: 8. Shareholders, Cap Table & TOSI (Tax on Split Income) Risk
A3: Shareholder Name | B3: Relationship to Principal | C3: Share Class | D3: Ownership % (Votes) | E3: Ownership % (Equity) | F3: Age | G3: Actively Engaged? (hrs/wk) | H3: Years Active in Business | I3: TOSI Status | J3: Other Personal Income ($) | K3: Notes
A4: Amara Okafor | B4: Self/Principal | C4: Common | D4: 0.6 | E4: 0.6 | F4: 44 | G4: 45 | H4: 8 | I4: Excluded - Age 25+, Meaningfully Contributes | J4: 0 | K4: Principal, full-time operator.
A5: Daniel Okafor | B5: Spouse/Common-Law Partner | C5: Class A | D5: 0.1 | E5: 0.1 | F5: 42 | G5: 5 | H5: 3 | I5: Not Excluded - TOSI Risk | J5: 95000 | K5: Works part-time in the business — under 20 hrs/wk average; TOSI risk on any dividend paid to this shareholder.
A6: Northern Peak Family Trust | B6: Family Trust | C6: Class B | D6: 0 | E6: 0.3 | G6: 0 | H6: 0 | I6: Pending Review by Accountant | J6: 0 | K6: Holds shares for adult child (age 22) — confirm excluded-shareholder test before any dividend.
A11: TOTAL | D11: =SUM(D4:D10) -> 0.7 | E11: =SUM(E4:E10) -> 1 | I11: =COUNTIF(I4:I10,"Not Excluded - TOSI Risk")&" shareholder(s) flagged for TOSI risk" -> 1 shareholder(s) flagged for TOSI risk | K11: Note: Votes % need not total 100% if any class is non-voting (e.g., the Family Trust's Class B shares carry no votes here).
A13: SHAREHOLDER LOANS (s.15(2) — taxable if not repaid within 1 year after corp year-end)
A14: Shareholder Name | B14: Loan Balance ($) | C14: Date Advanced | D14: Bona Fide Repayment Terms? | K14: Within 1-Year Repayment Rule?
A15: Daniel Okafor | B15: 25000 | C15: 2025-06-15 | D15: Yes | K15: Yes - due 2026-12-31 fiscal year-end + 1 yr

Sheet 9. Payroll Register
A1: 9. Payroll Register
A3: Employee/Owner Name | B3: Role | C3: Annual Salary/Wages ($) | D3: CPP Withheld ($) | E3: CPP2 Withheld ($) | F3: EI Withheld ($) | G3: Income Tax Withheld ($) | H3: Taxable Benefits ($) | I3: Province of Work | J3: Remittance Frequency
A4: Amara Okafor | B4: Owner-Manager | C4: 120000 | D4: 3867.5 | E4: 396 | F4: 0 | G4: 28000 | H4: 6000 | I4: Alberta | J4: Regular (Monthly)
A5: Priya Nair | B5: Senior Consultant | C5: 140000 | D5: 3867.5 | E5: 396 | F5: 1049.12 | G5: 30000 | H5: 0 | I5: Alberta | J5: Regular (Monthly)
A6: Jordan Lee | B6: Consultant | C6: 90000 | D6: 3867.5 | E6: 396 | F6: 1049.12 | G6: 17100 | H6: 0 | I6: Alberta | J6: Regular (Monthly)
A7: Sarah Bianchi | B7: Junior Consultant | C7: 70000 | D7: 3867.5 | E7: 0 | F7: 1049.12 | G7: 11900 | H7: 0 | I7: Alberta | J7: Regular (Monthly)
A8: Marc Tremblay | B8: Consultant (Ontario Office) | C8: 95000 | D8: 3867.5 | E8: 396 | F8: 1049.12 | G8: 18500 | H8: 0 | I8: Ontario | J8: Regular (Monthly)
A9: Chloe Martin | B9: Consultant (Ontario Office) | C9: 85000 | D9: 3867.5 | E9: 396 | F9: 1049.12 | G9: 15700 | H9: 0 | I9: Ontario | J9: Regular (Monthly)
A13: TOTAL | C13: =SUM(C4:C12) -> 600000 | D13: =SUM(D4:D12) -> 23205 | E13: =SUM(E4:E12) -> 1980 | F13: =SUM(F4:F12) -> 5245.6 | G13: =SUM(G4:G12) -> 121200 | H13: =SUM(H4:H12) -> 6000
A15: EMPLOYER PORTIONS & WCB
A16: Employer CPP Contribution (matches employee CPP, ~1x) | C16: =D13 -> 23205
A17: Employer CPP2 Contribution (matches employee CPP2, 1x) | C17: =E13 -> 1980
A18: Employer EI Contribution (1.4x employee EI) | C18: =F13*1.4 -> 7343.84
A19: WCB Assessable Payroll | C19: 600000
A20: WCB Premium Rate (per $100 of assessable payroll) | C20: 1.15 | D20: Province- and industry-classification-specific — confirm current rate with the provincial WCB/WSIB board.
A21: Estimated WCB Premium | C21: =C19/100*C20 -> 6900
A23: Notes: CPP2 applies above the base Year's Maximum Pensionable Earnings up to the Additional Maximum — figures shown are illustrative and change annually. Remittance frequency (Regular/Quarterly/Accelerated) is assigned by CRA based on average monthly withholding amounts (AMWA) two years prior — confirm current classification. Employees working from a different province than head office may require separate provincial payroll deductions and WCB registration in that province.

Sheet 10. GST-HST
A1: 10. GST/HST
A3: REGISTRATION
A4: GST/HST Registered? | C4: Yes
A5: Registration Effective Date | C5: 2016-04-01
A6: Filing Frequency | C6: Quarterly
A7: Operating in Quebec? (QST applies separately, filed with Revenu Québec) | C7: No
A9: SUPPLIES
A10: Taxable Supplies (revenue subject to GST/HST) | C10: ='3. Income Statement'!B9 -> 1200000
A11: Zero-Rated Supplies (e.g., exports, basic groceries) | C11: 0
A12: Exempt Supplies (e.g., certain financial/health/education services) | C12: 0
A14: GST/HST COLLECTED
A15: Province/Territory Rate Applied (auto from Entity Setup province) | C15: =INDEX('Province Rate Reference'!$F$5:$F$17,MATCH('1. Entity Setup'!$C$12,'Province Rate Reference'!$A$5:$A$17,0)) -> 0.05
A16: GST/HST Collected on Taxable Supplies | C16: =C10*C15 -> 60000
A18: INPUT TAX CREDITS (ITCs)
A19: General Operating Expense ITCs (100% eligible portion) | C19: 42000
A20: Meals & Entertainment ITCs (50% restricted) | C20: 4000 | D20: Only 50% of meals/entertainment GST/HST paid is claimable — linked at 50% of the Income Statement line.
A21: Passenger Vehicle ITCs (capped at prescribed amount) | C21: 750 | D21: ITC capped based on the CCA passenger-vehicle cost limit — confirm current prescribed amount.
A22: Capital Asset Purchase ITCs | C22: 1350
A25: Total ITCs | C25: =SUM(C19:C24) -> 48100
A27: NET TAX & INSTALMENTS
A28: Net Tax (GST/HST Owing / (Refund)) | C28: =C16-C25 -> 11900
A29: GST/HST Instalments Required? (net tax > $3,000 threshold, similar mechanism to income tax) | C29: =IF(C28>3000,"Yes - instalments likely required","No") -> Yes - instalments likely required

Sheet 11. Instalments & Compliance
A1: 11. Instalments & Compliance History
A3: INCOME TAX INSTALMENT THRESHOLD TEST
A4: Instalments are required if combined federal+provincial tax payable exceeded $3,000 in BOTH the current year estimate and either of the prior two years.
A5: Prior Year (Year -1) Tax Payable — Federal ($) | C5: 28500
A6: Prior Year (Year -1) Tax Payable — Provincial ($) | C6: 12100
A7: Prior Year (Year -2) Tax Payable — Federal ($) | C7: 24000
A8: Prior Year (Year -2) Tax Payable — Provincial ($) | C8: 10200
A10: Instalments Required? (based on prior 2 years, before current-year estimate) | C10: =IF(OR((C5+C6)>3000,(C7+C8)>3000),"Likely Yes — confirm vs. current-year Dashboard estimate","No") -> Likely Yes — confirm vs. current-year Dashboard estimate
A12: INSTALMENTS PAID THIS YEAR
A13: Date Paid | B13: Amount ($) | C13: Type (Federal/Provincial/GST) | D13: Notes
A14: 2025-03-31 | B14: 10125 | C14: Federal
A15: 2025-06-30 | B15: 10125 | C15: Federal
A16: 2025-09-30 | B16: 10125 | C16: Federal
A17: 2025-12-31 | B17: 10125 | C17: Federal
A20: Total Instalments Paid | B20: =SUM(B14:B19) -> 40500
A22: EXISTING CRA/PROVINCIAL BALANCES
A23: Balance Owing (Prior Assessments) | C23: 0
A24: Penalties Assessed | C24: 0
A25: Interest Assessed (non-deductible for tax purposes) | C25: 0
A26: GST/HST Remittance Standing | C26: Yes | D26: 'Yes' = in good standing / up to date.
A27: Payroll Remittance Standing | C27: Yes

Sheet 12. Credits & Incentives
A1: 12. Credits & Incentives
A3: SR&ED (SCIENTIFIC RESEARCH & EXPERIMENTAL DEVELOPMENT)
A4: SR&ED-Eligible Expenditures (current year, $) | C4: 65000
A5: SR&ED Expenditure Limit — Base ($3M federal cap) | C5: 3000000
A6: Expenditure Limit Grind — starts reducing once prior-year taxable income exceeds ~$500K, fully eliminated ~$800K; also reduced once group taxable capital exceeds $10M (eliminated at $50M).
A7: Prior-Year Taxable Income (this entity + associated group) | C7: 240000
A8: Enhanced 35% Refundable Rate Applies? (CCPC, under expenditure limit) | C8: Yes
A9: Estimated SR&ED Investment Tax Credit | C9: =C4*IF(C8="Yes",0.35,0.15) -> 22750
A11: PROVINCIAL CREDITS (varies by province selected on Entity Setup)
A12: Examples: Alberta Innovation Employment Grant (up to 20% of qualifying R&D spend above base), Ontario Innovation Tax Credit, BC SR&ED credit, Quebec provincial R&D credits, Manitoba R&D Tax Credit.
A13: Provincial Credit Program Name | C13: Alberta Innovation Employment Grant
A14: Provincial Credit Amount ($) | C14: 9750
A16: CHARITABLE DONATIONS
A17: Year | B17: Donation Amount ($) | C17: 5-Year Expiry | D17: Notes
A18: 2025 | B18: 8000 | C18: =A18+5 -> 2030 | D18: Corporate donations deduct against taxable income (not a credit) — 5-year carryforward if unused.
C19: =IF(A19=0,0,A19+5) -> 0

Sheet 13. Special Items
A1: 13. Special Items
A3: CORPORATELY OWNED LIFE INSURANCE
A4: Policy Owner | B4: Life Insured | C4: Face Amount ($) | D4: Cash Surrender Value ($) | E4: Adjusted Cost Basis ($) | F4: Annual Premium ($) | G4: Beneficiary | H4: Notes
A5: Northern Peak Consulting Inc. | B5: Amara Okafor | C5: 1000000 | D5: 35000 | E5: 18000 | F5: 6200 | G5: Corporation | H5: CDA credit on death = death benefit − ACB. Premiums are generally non-deductible for tax.
A9: FOREIGN INCOME / FOREIGN AFFILIATES
A10: Country | B10: Type of Income | C10: Amount ($) | D10: Foreign Tax Paid ($) | H10: Notes
A11: None | B11: N/A | C11: 0 | D11: 0 | H11: If present, FAPI (Foreign Accrual Property Income) rules may apply — materially more complex regime, requires professional review.
A14: PLANNED OR RECENT CORPORATE REORGANIZATION
A15: Share exchange, amalgamation, wind-up, estate freeze, or butterfly — these require professional sign-off regardless of this workbook's output.
A16: No reorganization planned or completed in the current fiscal year. Management is monitoring the passive-income grind on the Small Business Deduction and may consider an estate freeze or holding-company restructuring in a future year if investment income continues to grow — to be discussed with the corporation's accountant.

Sheet Province Rate Reference
A1: Province / Territory Rate Reference
A2: ⚠ ILLUSTRATIVE APPROXIMATIONS ONLY — verify every figure against current CRA and provincial published rates before use. Rates shown reflect general knowledge and may not reflect the current tax year.
A4: Province/Territory | B4: General Corp Rate (Fed+Prov) | C4: Small Business Rate (Fed+Prov) | D4: Provincial SBD Threshold | E4: GST/HST Type | F4: GST/HST Rate | G4: Notes
A5: Alberta | B5: 0.23 | C5: 0.11 | D5: 500000 | E5: GST only | F5: 0.05 | G5: AB has its own AT1 return — not fully CRA-administered.
A6: British Columbia | B6: 0.27 | C6: 0.11 | D6: 500000 | E6: GST only (+PST 7% separate) | F6: 0.05 | G6: PST is separate provincial sales tax, not part of GST/HST.
A7: Saskatchewan | B7: 0.27 | C7: 0.1 | D7: 500000 | E7: GST only (+PST 6% separate) | F7: 0.05 | G7: PST separate provincial sales tax.
A8: Manitoba | B8: 0.27 | C8: 0.09 | D8: 500000 | E8: GST only (+RST 7% separate) | F8: 0.05 | G8: RST separate; Manitoba small business rate historically 0%.
A9: Ontario | B9: 0.265 | C9: 0.122 | D9: 500000 | E9: HST | F9: 0.13 | G9: Ontario corporate return CRA-administered (harmonized).
A10: Quebec | B10: 0.265 | C10: 0.122 | D10: 500000 | E10: GST + QST (separate) | F10: 0.14975 | G10: QST administered by Revenu Québec, NOT CRA — separate filing.
A11: New Brunswick | B11: 0.29 | C11: 0.115 | D11: 500000 | E11: HST | F11: 0.15
A12: Nova Scotia | B12: 0.29 | C12: 0.115 | D12: 500000 | E12: HST | F12: 0.14 | G12: NS reduced HST rate — confirm effective date/rate before use.
A13: Prince Edward Island | B13: 0.31 | C13: 0.1 | D13: 500000 | E13: HST | F13: 0.15 | G13: Provincial SBD threshold raised to $500K in recent years — confirm.
A14: Newfoundland and Labrador | B14: 0.3 | C14: 0.115 | D14: 500000 | E14: HST | F14: 0.15 | G14: Provincial SBD threshold raised to $500K in recent years — confirm.
A15: Yukon | B15: 0.27 | C15: 0.09 | D15: 500000 | E15: GST only | F15: 0.05 | G15: Territorial small business rate historically 0%.
A16: Northwest Territories | B16: 0.265 | C16: 0.11 | D16: 500000 | E16: GST only | F16: 0.05
A17: Nunavut | B17: 0.27 | C17: 0.12 | D17: 500000 | E17: GST only | F17: 0.05
A19: Federal rates embedded above: general federal rate 15% (after abatement/general rate reduction); federal small business rate 9% on the first $500,000 of active business income (subject to the passive-income and taxable-capital grinds — see Dashboard). CPP/EI figures live on the Payroll Register tab and change annually.

Sheet Lists
A1: Province/Territory | B1: YesNo | C1: CCA Class | D1: Remittance Frequency | E1: GST/HST Filing Frequency | F1: TOSI Status | G1: Relationship to Principal | H1: Share Class | I1: Corp Relationship | J1: Income Classification | K1: Dividend Type
A2: Alberta | B2: Yes | C2: Class 1 - Buildings (4%) | D2: Regular (Monthly) | E2: Monthly | F2: Excluded - Age 25+, Meaningfully Contributes | G2: Self/Principal | H2: Common | I2: Parent | J2: Active Business Income | K2: Eligible Dividend
A3: British Columbia | B3: No | C3: Class 8 - Furniture & Equipment (20%) | D3: Quarterly (New Small Employer) | E3: Quarterly | F3: Excluded - Actively Engaged 20hrs/wk (5-yr test) | G3: Spouse/Common-Law Partner | H3: Class A | I3: Subsidiary | J3: Aggregate Investment Income | K3: Non-Eligible (Ordinary) Dividend
A4: Saskatchewan | B4: Pending | C4: Class 10 - Vehicles (30%) | D4: Accelerated Threshold 1 | E4: Annually | F4: Excluded - Age 18-24, Arm's-Length Capital Only | G4: Child (Adult) | H4: Class B | I4: Sister/Affiliate (Common Ownership) | J4: Foreign Income | K4: Capital Dividend (CDA)
A5: Manitoba | C5: Class 10.1 - Luxury Vehicles (30%) | D5: Accelerated Threshold 2 | F5: Excluded - Inherited Property | G5: Child (Minor) | H5: Class C - Preferred (Estate Freeze) | I5: Same Shareholder Group | J5: Exempt/Other
A6: Ontario | C6: Class 12 - Tools/Software (100%) | F6: Not Excluded - TOSI Risk | G6: Parent | H6: Other Preferred
A7: Quebec | C7: Class 13 - Leasehold Improvements | F7: Pending Review by Accountant | G7: Sibling
A8: New Brunswick | C8: Class 14.1 - Goodwill/Intangibles (5%) | G8: Family Trust
A9: Nova Scotia | C9: Class 50 - Computer Equipment (55%) | G9: Arm's Length
A10: Prince Edward Island | C10: Class 53 - Manufacturing Equipment (30%)
A11: Newfoundland and Labrador | C11: Other
A12: Yukon
A13: Northwest Territories
A14: Nunavut
